Workbook

Sheet Kitap
B1: 3D Yayınları TYT Türkçe Soru Bankası
B2: ISBN: | C2: 9786051949314
B3: Yayınevi: | C3: 3D Yayınları
B4: Kitap ID: | C4: 23063
G7: Not: Boş satırlarda TestNo otomatik hesaplanır, aynı konu için sırayla artar.
A8: KONULAR VE TESTLER | J8: ABCDE formatında girin | K8: Çözüm linkleri için virgülle ayırın
A9: KONUID | B9: SIRANO | C9: KonuKodu | D9: KonuAdı(UKS) | E9: Konu Adı(Kitap) | F9: TestID | G9: TestNo | H9: SoruSayisi | I9: TestTuru | J9: Cevaplar | K9: Cozumler
D10: =IFERROR(VLOOKUP(C10,Konular!$C:$D,2,0),"") | G10: =IF(C10<>"", IF(C10=C9,G9+1,1), "")
D11: =IFERROR(VLOOKUP(C11,Konular!$C:$D,2,0),"") | G11: =IF(C11<>"", IF(C11=C10,G10+1,1), "")
D12: =IFERROR(VLOOKUP(C12,Konular!$C:$D,2,0),"") | G12: =IF(C12<>"", IF(C12=C11,G11+1,1), "")
D13: =IFERROR(VLOOKUP(C13,Konular!$C:$D,2,0),"") | G13: =IF(C13<>"", IF(C13=C12,G12+1,1), "")
D14: =IFERROR(VLOOKUP(C14,Konular!$C:$D,2,0),"") | G14: =IF(C14<>"", IF(C14=C13,G13+1,1), "")
D15: =IFERROR(VLOOKUP(C15,Konular!$C:$D,2,0),"") | G15: =IF(C15<>"", IF(C15=C14,G14+1,1), "")
D16: =IFERROR(VLOOKUP(C16,Konular!$C:$D,2,0),"") | G16: =IF(C16<>"", IF(C16=C15,G15+1,1), "")
D17: =IFERROR(VLOOKUP(C17,Konular!$C:$D,2,0),"") | G17: =IF(C17<>"", IF(C17=C16,G16+1,1), "")
D18: =IFERROR(VLOOKUP(C18,Konular!$C:$D,2,0),"") | G18: =IF(C18<>"", IF(C18=C17,G17+1,1), "")
D19: =IFERROR(VLOOKUP(C19,Konular!$C:$D,2,0),"") | G19: =IF(C19<>"", IF(C19=C18,G18+1,1), "")
D20: =IFERROR(VLOOKUP(C20,Konular!$C:$D,2,0),"") | G20: =IF(C20<>"", IF(C20=C19,G19+1,1), "")
D21: =IFERROR(VLOOKUP(C21,Konular!$C:$D,2,0),"") | G21: =IF(C21<>"", IF(C21=C20,G20+1,1), "")
... D29: =IFERROR(VLOOKUP(C29,Konular!$C:$D,2,0),"") | G29: =IF(C29<>"", IF(C29=C28,G28+1,1), "")

Sheet TestTuru
A1: Test Türü Adı | B1: Id
A2: TEST | B2: 1
A3: TIRMANMA | B3: 2
A4: ÖSYM | B4: 3
A5: KAZANIM | B5: 4
A6: TARAMA | B6: 5
A7: BONUS | B7: 6
A8: Guzel | B8: 7
A9: YAPRAK TEST | B9: 8
A10: OPTİMUM TEST | B10: 10
A11: ZİRVE TEST | B11: 11
A12: ÜNİTE ANALİZ TESTİ | B12: 12
A13: KAVRAMA | B13: 13
... A12873: 12 | B12873: 24853
B12874: 24855
A12875: MATEMATİK KTT | B12875: 24856
A12876: TEST 1 | B12876: 24857
A12877: TEST 2 | B12877: 24858
A12878: YKİM1_PERSİS_BA01_S75 | B12878: 25202
A12879: YKİM1_PERSİS_BA02_S77 | B12879: 25203
A12880: YKİM1_PERSİS_GE01_S79 | B12880: 25204
A12881: YKİM1_PERSİS_GE02_S81 | B12881: 25205
A12882: YKİM1_PERSİS_GU01_S83 | B12882: 25206
A12883: YKİM1_DERBİT_DB01_S85 | B12883: 25207
A12884: YKİM1_MASTES_MT01_S87 | B12884: 25208
A12885: YFİZ1_FİZBİL_KA01_S3 | B12885: 25209
A12886: YFİZ1_FİZBİL_OS01_S3 | B12886: 25210
... A15061: 07-Bir Paragrafa Bağlı Sorular | B15061: 27387
B15062: 27388
A15063: Test-03 (İşlemsiz) | B15063: 27389
A15064: Test-05 (İşlemsiz) | B15064: 27390
A15065: Test-06 (İşlemsiz) | B15065: 27391
A15066: Test-02 (İşlemsiz) | B15066: 27392
A15067: Test-04 (İşlemsiz) | B15067: 27393
A15068: 01-Alıştıran Test-01 | B15068: 27394
A15069: 02-Alıştıran Test-02 | B15069: 27395
A15070: 03-Geliştiren Test-03 | B15070: 27396
A15071: 04-Çıkmış Sorular-04 | B15071: 27397
A15072: 05-Gölge Test-05 | B15072: 27398
A15073: 06-Alıştıran Test-06 | B15073: 27399
...

Sheet Konular
A1: Sınıf | B1: Ders | C1: Konu kodu | D1: Konu
A2: 5 | B2: Türkçe | C2: 15100 | D2: Parçada Anlam (Yapı)
A3: 5 | B3: Türkçe | C3: 15110 | D3: Giriş Gelişme Sonuç
A4: 5 | B4: Türkçe | C4: 15120 | D4: Parça Oluşturma
A5: 5 | B5: Türkçe | C5: 15130 | D5: Parça Tamamlama
A6: 5 | B6: Türkçe | C6: 15140 | D6: Geçiş İfadeleri
A7: 5 | B7: Türkçe | C7: 15150 | D7: Bağlantı İfadeleri
A8: 5 | B8: Türkçe | C8: 15160 | D8: Olayların Oluş Sırası
A9: 5 | B9: Türkçe | C9: 15200 | D9: Yazım Kuralları
A10: 5 | B10: Türkçe | C10: 15210 | D10: Büyük Küçük Harf
A11: 5 | B11: Türkçe | C11: 15220 | D11: Sayıların Yazımı
A12: 5 | B12: Türkçe | C12: 15300 | D12: Noktalama İşaretleri
A13: 5 | B13: Türkçe | C13: 15400 | D13: Metin Türleri
... A822: 2 | B822: Türkçe | C822: 99050 | D822: Yazma stratejilerini uygular.
A823: 2Y | B823: Türkçe | C823: 251100 | D823: DİNLEME / İZLEME
A824: 2Y | B824: Türkçe | C824: 251110 | D824: Dinlediklerinin konusu
A825: 2Y | B825: Türkçe | C825: 251120 | D825: Dinlediklerinde geçen anahtar kelimeler
A826: 2Y | B826: Türkçe | C826: 251130 | D826: Dinlediklerinden önemli bilgileri ayırt eder
A827: 2Y | B827: Türkçe | C827: 251140 | D827: Dinlediklerine uygun sorular sorar
A828: 2Y | B828: Türkçe | C828: 251150 | D828: Dinlediklerine ilişkin sorulara cevap verir
A829: 2Y | B829: Türkçe | C829: 251160 | D829: Dinleme sırasında dikkatini sürdürür
A830: 2Y | B830: Türkçe | C830: 251170 | D830: Dinleme kurallarına uyar
A831: 2Y | B831: Türkçe | C831: 251200 | D831: KONUŞMA
A832: 2Y | B832: Türkçe | C832: 251210 | D832: Duygu ve düşüncelerini açık ve anlaşılır biçimde ifade eder
A833: 2Y | B833: Türkçe | C833: 251220 | D833: Günlük olaylar hakkında konuşur
A834: 2Y | B834: Türkçe | C834: 251240 | D834: Konuşurken uygun ses tonu kullanır
... A1388: 10Y | B1388: Türkçe | C1388: 50601012 | D1388: İslamiyet Öncesi Türk Edebiyatı
